Workbook

Sheet All
A1: No. | B1: Nomeklatur/ Nama Daerah Irigasi | C1: Luas Daerah Irigasi Sesuai Permen 14/2015 (Ha) | D1: Lokasi Kabupaten/Kota | E1: Kode D.I
A2: 1 | B2: D.I. Dam Ombul | C2: 1085 | D2: Kabupaten Bangkalan | E2: 35000184
A3: 2 | B3: D.I. Tunjung | C3: 1807 | D3: Kabupaten Bangkalan | E3: 35000185
A4: 3 | B4: D.I. Blambangan | C4: 1523 | D4: Kabupaten Banyuwangi | E4: 35000155
A5: 4 | B5: D.I. Gembleng | C5: 1736 | D5: Kabupaten Banyuwangi | E5: 35000153
A6: 5 | B6: D.I. Tenggoro | C6: 1074 | D6: Kabupaten Banyuwangi | E6: 35000154
A7: 6 | B7: D.I. Dermen | C7: 1763 | D7: Kabupaten Blitar | E7: 35000194
A8: 7 | B8: D.I. Cawak | C8: 1733 | D8: Kabupaten Bojonegoro | E8: 35000134
A9: 8 | B9: D.I. Pirang | C9: 1347 | D9: Kabupaten Bojonegoro | E9: 35000133
A10: 9 | B10: D.I. Wd. Leran | C10: 1144 | D10: Kabupaten Bojonegoro | E10: 35000132
A11: 10 | B11: D.I. Balud | C11: 1074 | D11: Kabupaten Bondowoso | E11: 35000149
A12: 11 | B12: D.I. Wonosroyo | C12: 1499 | D12: Kabupaten Bondowoso | E12: 35000150
A13: 12 | B13: D.I. Kali Wadak | C13: 1476 | D13: Kabupaten Gresik | E13: 35000147
... A179: 178 | B179: D.I. P. Kaligerman | C179: 1120 | D179: Kab. Lamongan | E179: 35000140

Sheet Sheet1

Sheet per kab
A1: Daftar User Name Aplikasi EPAKSI Daerah Irigasi Kewenangan Pemerintah Provinsi Jawa Timur
A2: No. | B2: Nomeklatur/ Nama Daerah Irigasi | C2: Luas Daerah Irigasi Sesuai Permen 14/2015 (Ha) | D2: Lokasi Kabupaten/Kota | E2: Kode D.I
A3: I | B3: UPT PSDA WS Brantas (Korwil Malang) | F3: 1 | G3: Kab/Kota Malang | K3: =+SUM(C4:C8,C10:C11,C13:C23) -> 4041 | L3: 18
A4: 1 | B4: D.I. Bakalan | C4: 148 | D4: Kab./Kota Malang | E4: 35000001 | F4: 2 | G4: Kab. Malang, Kota Batu | K4: =+C9+C12 -> 739 | L4: 2
A5: 2 | B5: D.I. Bodo | C5: 156 | D5: Kab./Kota Malang | E5: 35000002 | F5: 3 | G5: Kab. Blitar, Kab. Tulungagung | K5: =+C24 -> 165 | L5: 1
A6: 3 | B6: D.I. Kadalpang | C6: 1212 | D6: Kab./Kota Malang | E6: 35000003 | F6: 4 | G6: Kab. Trenggalek, Kab. Tulungagung | K6: =+C25+C40+C41 -> 5423 | L6: 3
A7: 4 | B7: D.I. Kajar II A | C7: 20 | D7: Kab./Kota Malang | E7: 35000004 | F7: 5 | G7: Kab./Kota Blitar | K7: =+SUM(C26:C35) -> 522 | L7: 10
A8: 5 | B8: D.I. Kali Metro | C8: 527 | D8: Kab./Kota Malang | E8: 35000005 | F8: 6 | G8: Kab. Blitar, Kab. Kediri | K8: =+C36 -> 461 | L8: 1
A9: 6 | B9: D.I. Kalilanang | C9: 457 | D9: Kab. Malang, Kota Batu | E9: 35000006 | F9: 7 | G9: Kabupaten Blitar | K9: =+C37 -> 1763 | L9: 1
A10: 7 | B10: D.I. Kebalon | C10: 107 | D10: Kab./Kota Malang | E10: 35000007 | F10: 8 | G10: Kabupaten Tulungagung | K10: =+C38 -> 1378 | L10: 1
A11: 8 | B11: D.I. Losawi | C11: 39 | D11: Kab./Kota Malang | E11: 35000008 | F11: 9 | G11: Kab./Kota Kediri | K11: =+SUM(C42:C50) -> 1653 | L11: 9
A12: 9 | B12: D.I. Ngukir | C12: 282 | D12: Kab. Malang, Kota Batu | E12: 35000009 | F12: 10 | G12: Kabupaten Kediri | K12: =+SUM(C51:C52) -> 2723 | L12: 2
A13: 10 | B13: D.I. Pakis | C13: 726 | D13: Kab./Kota Malang | E13: 35000010 | F13: 11 | G13: Kabupaten Nganjuk | K13: =+SUM(C53:C55) -> 3866 | L13: 3
A14: 11 | B14: D.I. Peniwen | C14: 63 | D14: Kab./Kota Malang | E14: 35000011 | F14: 12 | G14: Kabupaten Jombang | K14: =+SUM(C56:C57) -> 2994 | L14: 2
A15: 12 | B15: D.I. Podokaton | C15: 70 | D15: Kab./Kota Malang | E15: 35000012 | F15: 13 | G15: Kab. Jombang, Kab. Kediri | K15: =+C58 -> 445 | L15: 1
A16: 13 | B16: D.I. Sedudut | C16: 53 | D16: Kab./Kota Malang | E16: 35000013 | F16: 14 | G16: Kab. Jombang, Kab. Mojokerto | K16: =+SUM(C60:C63) -> 1080 | L16: 4
A17: 14 | B17: D.I. Sengkaling Kanan | C17: 193 | D17: Kab./Kota Malang | E17: 35000014 | F17: 15 | G17: Kab./Kota Mojokerto | K17: =+SUM(C64:C68) -> 4328 | L17: 5
A18: 15 | B18: D.I. Sengkaling Kiri | C18: 455 | D18: Kab./Kota Malang | E18: 35000015 | F18: 16 | G18: Kabupaten Mojokerto | K18: =+C69 -> 1055 | L18: 1
A19: 16 | B19: D.I. Sumber Tekik | C19: 16 | D19: Kab./Kota Malang | E19: 35000016 | F19: 17 | G19: Kab. Lamongan, Kab. Tuban | K19: =+C71 -> 2143 | L19: 1
A20: 17 | B20: D.I. Sumber Turus | C20: 32 | D20: Kab./Kota Malang | E20: 35000017 | F20: 18 | G20: Kab. Gresik, Kab. Lamongan | K20: =+SUM(C72:C73) -> 3867 | L20: 2
A21: 18 | B21: D.I. Trimo Semut | C21: 46 | D21: Kab./Kota Malang | E21: 35000018 | F21: 19 | G21: Kabupaten Bojonegoro | K21: =+SUM(C74:C76) -> 4224 | L21: 3
A22: 19 | B22: D.I. Urung-Urung | C22: 59 | D22: Kab./Kota Malang | E22: 35000019 | F22: 20 | G22: Kabupaten Tuban | K22: =+SUM(C77:C80) -> 6518 | L22: 4
A23: 20 | B23: D.I. Turi | C23: 119 | D23: Kab./Kota Malang | E23: 35003010 | F23: 21 | G23: Kabupaten Lamongan | K23: =+SUM(C81:C86) -> 8063 | L23: 6
A24: 21 | B24: D.I. Kaliboto | C24: 165 | D24: Kab. Blitar, Kab. Tulungagung | E24: 35000021 | F24: 22 | G24: Kabupaten Gresik | K24: =+SUM(C87:C89) -> 3960 | L24: 3
A25: 22 | B25: D.I. Paingan | C25: 551 | D25: Kab. Trenggalek, Kab. Tulungagung | E25: 35000022 | F25: 23 | G25: Kab./Kota Madiun | K25: =+SUM(C91:C97) -> 4198 | L25: 7
A26: 23 | B26: D.I. Sukorame | C26: 69 | D26: Kab./Kota Blitar | E26: 35000024 | F26: 24 | G26: Kab. Madiun, Kab. Ngawi | K26: =+C98 -> 1554 | L26: 1
A27: 24 | B27: D.I. Jempor | C27: 54 | D27: Kab./Kota Blitar | E27: 35000025 | F27: 25 | G27: Kab. Madiun, Kab. Magetan | K27: =+C99 -> 745 | L27: 1
A28: 25 | B28: D.I. Tambakrejo I | C28: 23 | D28: Kab./Kota Blitar | E28: 35000026 | F28: 26 | G28: Kab. Magetan, Kab. Ponorogo | K28: =+C100+C110 -> 284 | L28: 2
A29: 26 | B29: D.I. Rembang | C29: 42 | D29: Kab./Kota Blitar | E29: 35000027 | F29: 27 | G29: Kab. Magetan, Kab. Ngawi | K29: =+SUM(C101:C109) -> 4747 | L29: 9
A30: 27 | B30: D.I. Plosotengah | C30: 51 | D30: Kab./Kota Blitar | E30: 35000028 | F30: 28 | G30: Kabupaten Madiun | K30: =+SUM(C111:C115) -> 7141 | L30: 5
A31: 28 | B31: D.I. Sawahan | C31: 82 | D31: Kab./Kota Blitar | E31: 35000029 | F31: 29 | G31: Kabupaten Ponorogo | K31: =+SUM(C116:C121) -> 8383 | L31: 6
A32: 29 | B32: D.I. Ngrebo | C32: 62 | D32: Kab./Kota Blitar | E32: 35000030 | F32: 30 | G32: Kabupaten Ngawi | K32: =+SUM(C122:C129) -> 11740 | L32: 8
A33: 30 | B33: D.I. Jatinom | C33: 56 | D33: Kab./Kota Blitar | E33: 35000032 | F33: 31 | G33: Kab./Kota Probolinggo | K33: =+SUM(C131:C137) -> 2206 | L33: 7
A34: 31 | B34: D.I. Sumber Tulung | C34: 38 | D34: Kab./Kota Blitar | E34: 35000033 | F34: 32 | G34: Kab./Kota Pasuruan | K34: =+SUM(C138:C141) -> 4035 | L34: 4
A35: 32 | B35: D.I. Sumber Berjo | C35: 45 | D35: Kab./Kota Blitar | E35: 35000038 | F35: 33 | G35: Kab. Malang, Kab. Pasuruan | K35: =+C142 -> 876 | L35: 1
A36: 33 | B36: D.I. Jaten Termas | C36: 461 | D36: Kab. Blitar, Kab. Kediri | E36: 35000039 | F36: 34 | G36: Kabupaten Probolinggo | K36: =+SUM(C143:C147) -> 7815 | L36: 5
A37: 34 | B37: D.I. Dermen | C37: 1763 | D37: Kabupaten Blitar | E37: 35000194 | F37: 35 | G37: Kabupaten Pasuruan | K37: =+SUM(C148:C155) -> 10277 | L37: 8
A38: 35 | B38: D.I. Gelang | C38: 1378 | D38: Kabupaten Tulungagung | E38: 35000095 | F38: 36 | G38: Kabupaten Jember | K38: =+SUM(C157:C164) -> 13769 | L38: 5
A39: II | B39: UPT PSDA WS Brantas | F39: 37 | G39: Kabupaten Lumajang | K39: =+SUM(C165:C169) -> 7231 | L39: 8
A40: 1 | B40: D.I. Sbr. Gayam | C40: 1926 | D40: Kab. Trenggalek, Kab. Tulungagung | E40: 35000020 | F40: 38 | G40: Kab. Bondowoso, Kab. Jember | K40: =+SUM(C171:C172) -> 1470 | L40: 2
...

Sheet Luas DI
A2: 1 | B2: 13 | E2: Luas DI | F2: Persentase | M2: 1 | N2: 13
A3: 2 | B3: 16 | E3: =+N85 -> 22543 | F3: =+E3/$E$5 -> 0.13488464 | G3: <1000 ha | M3: 2 | N3: 16
A4: 3 | B4: 20 | E4: =+N183 -> 144585 | F4: =+E4/$E$5 -> 0.86511536 | G4: 1000-3000 ha | M4: 3 | N4: 20
A5: 4 | B5: 23 | E5: =SUM(E3:E4) -> 167128 | F5: =SUM(F3:F4) -> 1 | M5: 4 | N5: 20
A6: 5 | B6: 32 | M6: 5 | N6: 23
A7: 6 | B7: 38 | M7: 6 | N7: 32
A8: 7 | B8: 38 | M8: 7 | N8: 38
A9: 8 | B9: 39 | M9: 8 | N9: 38
A10: 9 | B10: 42 | M10: 9 | N10: 39
A11: 10 | B11: 45 | M11: 10 | N11: 42
A12: 11 | B12: 46 | M12: 11 | N12: 45
A13: 12 | B13: 50 | M13: 12 | N13: 46
A14: 13 | B14: 51 | M14: 13 | N14: 50
A15: 14 | B15: 53 | M15: 14 | N15: 51
A16: 15 | B16: 54 | M16: 15 | N16: 53
A17: 16 | B17: 54 | M17: 16 | N17: 54
... A74: 73 | B74: 971 | M74: 73 | N74: 638
B75: =SUM(B2:B74) -> 18803 | M75: 74 | N75: 661
M76: 75 | N76: 684
A77: 1 | B77: 1000 | M77: 76 | N77: 695
A78: 2 | B78: 1008 | M78: 77 | N78: 696
A79: 3 | B79: 1044 | M79: 78 | N79: 726
A80: 4 | B80: 1045 | M80: 79 | N80: 745
A81: 5 | B81: 1046 | M81: 80 | N81: 777
A82: 6 | B82: 1055 | M82: 81 | N82: 789
A83: 7 | B83: 1057 | M83: 82 | N83: 876
A84: 8 | B84: 1058 | M84: 83 | N84: 971
A85: 9 | B85: 1074 | N85: =SUM(N2:N84) -> 22543
A86: 10 | B86: 1074
A87: 11 | B87: 1085
A88: 12 | B88: 1086 | M88: 1 | N88: 1000
A89: 13 | B89: 1088 | M89: 2 | N89: 1008
A90: 14 | B90: 1090 | M90: 3 | N90: 1044
A91: 15 | B91: 1094 | M91: 4 | N91: 1045
A92: 16 | B92: 1096 | M92: 5 | N92: 1046
A93: 17 | B93: 1120 | M93: 6 | N93: 1054
A94: 18 | B94: 1126 | M94: 7 | N94: 1055
A95: 19 | B95: 1144 | M95: 8 | N95: 1057
A96: 20 | B96: 1146 | M96: 9 | N96: 1058
A97: 21 | B97: 1151 | M97: 10 | N97: 1074
...

Sheet fisik
AJ1: REKAPITULASI KONDISI PRASARANA FISIK DAERAH IRIGASI KEWENANGAN PEMERINTAH PROVINSI JAWA TIMUR
H2: indeks | I2: luas | L2: kondisi | M2: jumlah D.I | N2: luas D.I | O2: jumlah D.I | P2: luas D.I | R2: kondisi | S2: jumlah D.I | U2: kondisi | V2: luas D.I | AC2: Luas | AD2: IKJI | AJ2: No. | AK2: Daerah Irigasi | AL2: Luas (Ha) | AM2: Lokasi | AN2: Indeks Kondisi Prasarana Fisik | AO2: Persenatase Kondisi Prasarana Fisik (%) | AP2: Kondisi
A3: 1 | B3: 39.23 | C3: =+B3/45 -> 0.87177778 | D3: baik | F3: jelek | G3: =+H3/45 -> 0.25111111 | H3: 11.3 | I3: 1475 | L3: Jelek | M3: =+COUNT(AN3:AN79) -> 77 | N3: =+SUM(AH3:AH78) -> 57266 | O3: =+M3/$M$6 -> 0.43258427 | P3: =+N3/$N$6 -> 0.34264755 | R3: =+L3 -> Jelek | S3: =+O3 -> 0.43258427 | U3: =+R3 -> Jelek | V3: =+P3 -> 0.34264755 | AB3: 1 | AC3: 1000 | AD3: 30 | AE3: D.I. CEPOGO | AG3: 1 | AH3: 45 | AI3: 5.3 | AJ3: 1 | AK3: D.I. SUMBER BERJO | AL3: 45 | AM3: Kab./Kota Blitar | AN3: 5.3 | AO3: =+AN3/45*100 -> 11.777778 | AP3: Rusak Berat
A4: 2 | B4: 38.83 | C4: =+B4/45 -> 0.86288889 | D4: baik | F4: jelek | G4: =+H4/45 -> 0.26733333 | H4: 12.03 | I4: 50 | L4: Sedang | M4: =+COUNT(AN80:AN177) -> 98 | N4: =+SUM(AH79:AH177) -> 103660 | O4: =+M4/$M$6 -> 0.5505618 | P4: =+N4/$N$6 -> 0.62024317 | R4: =+L4 -> Sedang | S4: =+O4 -> 0.5505618 | U4: =+R4 -> Sedang | V4: =+P4 -> 0.62024317 | AB4: 2 | AC4: 1403 | AD4: 21.53 | AE4: D.I. DALEM | AG4: 2 | AH4: 50 | AI4: 12.03 | AJ4: 2 | AK4: D.I. MOJOPURNO | AL4: 50 | AM4: Kab./Kota Madiun | AN4: 12.03 | AO4: =+AN4/45*100 -> 26.733333 | AP4: Rusak Berat
A5: 3 | B5: 38.12 | C5: =+B5/45 -> 0.84711111 | D5: baik | F5: jelek | G5: =+H5/45 -> 0.27644444 | H5: 12.44 | I5: 1120 | L5: Baik | M5: =+COUNT(AN178:AN180) -> 3 | N5: =+SUM(AH178:AH180) -> 6202 | O5: =+M5/$M$6 -> 0.016853933 | P5: =+N5/$N$6 -> 0.037109282 | R5: =+L5 -> Baik | S5: =+O5 -> 0.016853933 | U5: =+R5 -> Baik | V5: =+P5 -> 0.037109282 | AB5: 3 | AC5: 1370 | AD5: 30.94 | AE5: D.I. SAMPUNG | AG5: 3 | AH5: 151 | AI5: 12.05 | AJ5: 3 | AK5: D.I. LONTONG | AL5: 151 | AM5: Kab./Kota Probolinggo | AN5: 12.05 | AO5: =+AN5/45*100 -> 26.777778 | AP5: Rusak Berat
A6: 4 | B6: 37.79 | C6: =+B6/45 -> 0.83977778 | D6: baik | F6: jelek | G6: =+H6/45 -> 0.29733333 | H6: 13.38 | I6: 113 | M6: =SUM(M3:M5) -> 178 | N6: =SUM(N3:N5) -> 167128 | O6: =SUM(O3:O5) -> 1 | P6: =SUM(P3:P5) -> 1 | AB6: 4 | AC6: 1787 | AD6: 27.97 | AE6: D.I. SUMOROBANGUN | AG6: 4 | AH6: 1476 | AI6: 12.06 | AJ6: 4 | AK6: D.I. KALI WADAK | AL6: 1476 | AM6: Kab. Gresik | AN6: 12.06 | AO6: =+AN6/45*100 -> 26.8 | AP6: Rusak Berat
A7: 5 | B7: 37.57 | C7: =+B7/45 -> 0.83488889 | D7: baik | F7: jelek | G7: =+H7/45 -> 0.29888889 | H7: 13.45 | I7: 281 | AB7: 5 | AC7: 1096 | AD7: 25.69 | AE7: D.I. WATU PUTIH | AG7: 5 | AH7: 1120 | AI7: 12.44 | AJ7: 5 | AK7: D.I. KALIGERMAN | AL7: 1120 | AM7: Kab. Lamongan | AN7: 12.44 | AO7: =+AN7/45*100 -> 27.644444 | AP7: Rusak Berat
A8: 6 | B8: 36.95 | C8: =+B8/45 -> 0.82111111 | D8: baik | F8: jelek | G8: =+H8/45 -> 0.30666667 | H8: 13.8 | I8: 51 | AB8: 6 | AC8: 1727 | AD8: 29.38 | AE8: D.I. WILANGAN | AG8: 6 | AH8: 1054 | AI8: 13.04 | AJ8: 6 | AK8: D.I. WD. GOGOR | AL8: 1054 | AM8: Kab. Gresik | AN8: 13.04 | AO8: =+AN8/45*100 -> 28.977778 | AP8: Rusak Berat
A9: 7 | B9: 36.72 | C9: =+B9/45 -> 0.816 | D9: baik | F9: jelek | G9: =+H9/45 -> 0.30888889 | H9: 13.9 | I9: 13 | AB9: 7 | AC9: 1378 | AD9: 23.96 | AE9: D.I. GELANG | AG9: 7 | AH9: 113 | AI9: 13.38 | AJ9: 7 | AK9: D.I. BUJEL | AL9: 113 | AM9: Kab./Kota Kediri | AN9: 13.38 | AO9: =+AN9/45*100 -> 29.733333 | AP9: Rusak Berat
A10: 8 | B10: 36.45 | C10: =+B10/45 -> 0.81 | D10: baik | F10: jelek | G10: =+H10/45 -> 0.32311111 | H10: 14.54 | I10: 1779 | AB10: 8 | AC10: 1763 | AD10: 33.18 | AE10: D.I. DERMEN | AG10: 8 | AH10: 51 | AI10: 13.8 | AJ10: 8 | AK10: D.I. PLOSOTENGAH | AL10: 51 | AM10: Kab./Kota Blitar | AN10: 13.8 | AO10: =+AN10/45*100 -> 30.666667 | AP10: Rusak Berat
A11: 9 | B11: 35.97 | C11: =+B11/45 -> 0.79933333 | D11: sedang | F11: jelek | G11: =+H11/45 -> 0.33444444 | H11: 15.05 | I11: 209 | AB11: 9 | AC11: 1637 | AD11: 32 | AE11: D.I. KETANDAN | AG11: 9 | AH11: 13 | AI11: 13.9 | AJ11: 9 | AK11: D.I. JABUNG | AL11: 13 | AM11: Kab. Ngawi/Kab. Magetan | AN11: 13.9 | AO11: =+AN11/45*100 -> 30.888889 | AP11: Rusak Berat
A12: 10 | B12: 32 | C12: =+B12/45 -> 0.71111111 | D12: sedang | F12: jelek | G12: =+H12/45 -> 0.35755556 | H12: 16.09 | I12: 1799 | AB12: 10 | AC12: 1086 | AD12: 30 | AE12: D.I. POHBLEMBEM | AG12: 10 | AH12: 1779 | AI12: 14.54 | AJ12: 10 | AK12: D.I. RAWA SEKARAN | AL12: 1779 | AM12: Kab. Lamongan | AN12: 14.54 | AO12: =+AN12/45*100 -> 32.311111 | AP12: Rusak Berat
A13: 11 | B13: 31.96 | C13: =+B13/45 -> 0.71022222 | D13: sedang | F13: jelek | G13: =+H13/45 -> 0.37822222 | H13: 17.02 | I13: 194 | AB13: 11 | AC13: 1094 | AD13: 32.12 | AE13: D.I. BRUG PURWO | AG13: 11 | AH13: 209 | AI13: 15.05 | AJ13: 11 | AK13: D.I. KULUHAN | AL13: 209 | AM13: Kab. Ngawi/Kab. Magetan | AN13: 15.05 | AO13: =+AN13/45*100 -> 33.444444 | AP13: Rusak Berat
A14: 12 | B14: 31.88 | C14: =+B14/45 -> 0.70844444 | D14: sedang | F14: jelek | G14: =+H14/45 -> 0.38333333 | H14: 17.25 | I14: 38 | AB14: 12 | AC14: 1867 | AD14: 33.12 | AE14: D.I. CURAH MENJANGAN/KEDUNGSANGKU | AG14: 12 | AH14: 62 | AI14: 15.95 | AJ14: 12 | AK14: D.I. WARUJINGGO | AL14: 62 | AM14: Kab./Kota Probolinggo | AN14: 15.95 | AO14: =+AN14/45*100 -> 35.444444 | AP14: Rusak Berat
A15: 13 | B15: 31.79 | C15: =+B15/45 -> 0.70644444 | D15: sedang | F15: jelek | G15: =+H15/45 -> 0.39422222 | H15: 17.74 | I15: 1055 | AB15: 13 | AC15: 1088 | AD15: 21.64 | AE15: D.I. JURANG DAWIR | AG15: 13 | AH15: 281 | AI15: 16.15 | AJ15: 13 | AK15: D.I. KEMBANGAN | AL15: 281 | AM15: Kab./Kota Kediri | AN15: 16.15 | AO15: =+AN15/45*100 -> 35.888889 | AP15: Rusak Berat
A16: 14 | B16: 30.94 | C16: =+B16/45 -> 0.68755556 | D16: sedang | F16: jelek | G16: =+H16/45 -> 0.39933333 | H16: 17.97 | I16: 551 | AB16: 14 | AC16: 1920 | AD16: 22.26 | AE16: D.I. TEKUNG I | AG16: 14 | AH16: 1475 | AI16: 16.59 | AJ16: 14 | AK16: D.I. MERAK URAK | AL16: 1475 | AM16: Kab. Tuban | AN16: 16.59 | AO16: =+AN16/45*100 -> 36.866667 | AP16: Rusak Berat
A17: 15 | B17: 30.8 | C17: =+B17/45 -> 0.68444444 | D17: sedang | F17: jelek | G17: =+H17/45 -> 0.41888889 | H17: 18.85 | I17: 1008 | AB17: 15 | AC17: 1262 | AD17: 23.34 | AE17: D.I. UMBUL PRINGTALI | AG17: 15 | AH17: 38 | AI17: 17.25 | AJ17: 15 | AK17: D.I. SUMBER TULUNG | AL17: 38 | AM17: Kab./Kota Blitar | AN17: 17.25 | AO17: =+AN17/45*100 -> 38.333333 | AP17: Rusak Berat
A18: 16 | B18: 30.77 | C18: =+B18/45 -> 0.68377778 | D18: sedang | F18: jelek | G18: =+H18/45 -> 0.42733333 | H18: 19.23 | I18: 1661 | AB18: 16 | AC18: 2188 | AD18: 30.37 | AE18: D.I. BAGO | AG18: 16 | AH18: 527 | AI18: 19.29 | AJ18: 16 | AK18: D.I. KALI METRO | AL18: 527 | AM18: Kab./Kota Malang | AN18: 19.29 | AO18: =+AN18/45*100 -> 42.866667 | AP18: Rusak Berat
... A160: 158 | B160: 11.3 | C160: =+B160/45 -> 0.25111111 | D160: jelek | F160: baik | G160: =+H160/45 -> 0.87177778 | H160: 39.23 | I160: 1523 | AB160: 158 | AC160: 309 | AD160: 26.08 | AE160: D.I. NURBIHA | AG160: 158 | AH160: 319 | AI160: 32.48 | AJ160: 158 | AK160: D.I. ARJASA | AL160: 319 | AM160: Kab. Bondowoso/Kab.Jember | AN160: 32.48 | AO160: =+AN160/45*100 -> 72.177778 | AP160: Rusak Sedang
I161: =SUM(I3:I160) -> 149988 | AB161: 159 | AC161: 350 | AD161: 19.32 | AE161: D.I. GUMBOLO/DAWUHAN | AG161: 159 | AH161: 684 | AI161: 32.55 | AJ161: 159 | AK161: D.I. SONO | AL161: 684 | AM161: Kab. Madiun/Kota Madiun | AN161: 32.55 | AO161: =+AN161/45*100 -> 72.333333 | AP161: Rusak Sedang
AB162: 160 | AC162: 63 | AD162: 24.78 | AE162: D.I. PRINGDURI | AG162: 160 | AH162: 1211 | AI162: 32.61 | AJ162: 160 | AK162: D.I. BULAKMOJO | AL162: 1211 | AM162: Kab. Nganjuk | AN162: 32.61 | AO162: =+AN162/45*100 -> 72.466667 | AP162: Rusak Sedang
AB163: 161 | AC163: 777 | AD163: 32.61 | AE163: D.I. BAJULMATI | AG163: 161 | AH163: 777 | AI163: 32.61 | AJ163: 161 | AK163: D.I. BAJULMATI | AL163: 777 | AM163: Kab. Banyuwangi/Kab.Situbondo | AN163: 32.61 | AO163: =+AN163/45*100 -> 72.466667 | AP163: Rusak Sedang
AB164: 162 | AC164: 80 | AD164: 32 | AE164: D.I. SBR. NYAMPLONG | AG164: 162 | AH164: 1554 | AI164: 32.68 | AJ164: 162 | AK164: D.I. KEDUNGREJO | AL164: 1554 | AM164: Kab. Madiun/Kab.Ngawi | AN164: 32.68 | AO164: =+AN164/45*100 -> 72.622222 | AP164: Rusak Sedang
AB165: 163 | AC165: 190 | AD165: 26.75 | AE165: D.I. I.S PAKIS | AG165: 163 | AH165: 2581 | AI165: 32.97 | AJ165: 163 | AK165: D.I. TANGGULANGIN | AL165: 2581 | AM165: Kab. Pasuruan/Kota Pasuruan | AN165: 32.97 | AO165: =+AN165/45*100 -> 73.266667 | AP165: Rusak Sedang
AB166: 164 | AC166: 151 | AD166: 12.05 | AE166: D.I. LONTONG | AG166: 164 | AH166: 1879 | AI166: 32.98 | AJ166: 164 | AK166: D.I. KOTTOK | AL166: 1879 | AM166: Kab. Jember | AN166: 32.98 | AO166: =+AN166/45*100 -> 73.288889 | AP166: Rusak Sedang
AB167: 165 | AC167: 62 | AD167: 15.95 | AE167: D.I. WARUJINGGO | AG167: 165 | AH167: 2340 | AI167: 33.08 | AJ167: 165 | AK167: D.I. KEREP | AL167: 2340 | AM167: Kab. Magetan/Kab.Ngawi | AN167: 33.08 | AO167: =+AN167/45*100 -> 73.511111 | AP167: Rusak Sedang
AB168: 166 | AC168: 696 | AD168: 29.64 | AE168: D.I. TAPOSAN | AG168: 166 | AH168: 1393 | AI168: 33.1 | AJ168: 166 | AK168: D.I. SUMBER NANGKA | AL168: 1393 | AM168: Kab. Jember | AN168: 33.1 | AO168: =+AN168/45*100 -> 73.555556 | AP168: Rusak Sedang
AB169: 167 | AC169: 598 | AD169: 27.75 | AE169: D.I. KRASAK | AG169: 167 | AH169: 1867 | AI169: 33.12 | AJ169: 167 | AK169: D.I. CURAH MENJANGAN/KEDUNGSANGKU | AL169: 1867 | AM169: Kab. Lumajang | AN169: 33.12 | AO169: =+AN169/45*100 -> 73.6 | AP169: Rusak Sedang
AB170: 168 | AC170: 445 | AD170: 30.65 | AE170: D.I. MBOK SITI | AG170: 168 | AH170: 1763 | AI170: 33.18 | AJ170: 168 | AK170: D.I. DERMEN | AL170: 1763 | AM170: Kab. Blitar | AN170: 33.18 | AO170: =+AN170/45*100 -> 73.733333 | AP170: Rusak Sedang
AB171: 169 | AC171: 64 | AD171: 28.94 | AE171: D.I. BANGO | AG171: 169 | AH171: 2462 | AI171: 33.45 | AJ171: 169 | AK171: D.I. SAMIRAN | AL171: 2462 | AM171: Kab. Pamekasan | AN171: 33.45 | AO171: =+AN171/45*100 -> 74.333333 | AP171: Rusak Sedang
AB172: 170 | AC172: 695 | AD172: 22.73 | AE172: D.I. GRINTING | AG172: 170 | AH172: 2433 | AI172: 33.46 | AJ172: 170 | AK172: D.I. NOTOPURO | AL172: 2433 | AM172: Kab. Madiun | AN172: 33.46 | AO172: =+AN172/45*100 -> 74.355556 | AP172: Rusak Sedang
AB173: 171 | AC173: 463 | AD173: 23.63 | AE173: D.I. LICIN | AG173: 171 | AH173: 551 | AI173: 33.73 | AJ173: 171 | AK173: D.I. PAINGAN | AL173: 551 | AM173: Kab. Trenggalek/Kab. Tulungagung | AN173: 33.73 | AO173: =+AN173/45*100 -> 74.955556 | AP173: Rusak Sedang
... AB180: 178 | AC180: 1372 | AD180: 21.51 | AE180: D.I. WIDODAREN | AG180: 178 | AH180: 1807 | AI180: 39.49 | AJ180: 178 | AK180: D.I. TUNJUNG | AL180: 1807 | AM180: Kab. Bangkalan | AN180: 39.49 | AO180: =+AN180/45*100 -> 87.755556 | AP180: Rusak Ringan

Sheet Non fisik
B2: Produktivitas | C2: Sarana Penujang | D2: Organisasi Personalia | E2: Dokumentasi | F2: P3A/GP3A/IP3A | G2: jumlah | H2: luas | L2: jumlah | M2: luas | O2: kondisi | Q2: Jumlah D.I | S2: kondisi | U2: Luas D.I | W2: luas | X2: Produktivitas | Y2: Sarana Penujang | Z2: Organisasi Personalia | AA2: Dokumentasi | AB2: P3A/GP3A/IP3A | AC2: jumlah | AF2: luas | AG2: Non fisik
B3: 13.38 | C3: 6 | D3: 6.5 | E3: 3.1 | F3: 3.4 | G3: =+SUM(B3:F3) -> 32.38 | H3: 148 | J3: kurang | K3: =+L3/55 -> 0.43636364 | L3: 24 | M3: 1232 | O3: jelek | P3: =+Q3/$Q$6 -> 0.24157303 | Q3: =+COUNT(AH3:AH45) -> 43 | S3: =+O3 -> jelek | T3: 0.23 | U3: =+SUM(AF3:AF45) -> 37396 | V3: 1 | W3: 1000 | X3: 9.63 | Y3: 7.23 | Z3: 11.72 | AA3: 4.18 | AB3: 7 | AC3: =+SUM(X3:AB3) -> 39.76 | AE3: 1 | AF3: 1085 | AG3: 19.01 | AH3: =+AG3/55*100 -> 34.563636 | AI3: jelek
B4: 13.36 | C4: 6 | D4: 6.5 | E4: 3.1 | F4: 3 | G4: =+SUM(B4:F4) -> 31.96 | H4: 156 | J4: kurang | K4: =+L4/55 -> 0.45927273 | L4: 25.26 | M4: 455 | O4: sedang | P4: =+Q4/$Q$6 -> 0.65168539 | Q4: =+COUNT(AH46:AH161) -> 116 | S4: =+O4 -> sedang | T4: 0.67 | U4: =+SUM(AF46:AF161) -> 109583 | V4: 2 | W4: 1403 | X4: 14.91 | Y4: 8.5 | Z4: 11.1 | AA4: 4.25 | AB4: 6.55 | AC4: =+SUM(X4:AB4) -> 45.31 | AE4: 2 | AF4: 1132 | AG4: 19.8 | AH4: =+AG4/55*100 -> 36 | AI4: jelek
B5: 13.4 | C5: 6 | D5: 6.5 | E5: 2.9 | F5: 3.99 | G5: =+SUM(B5:F5) -> 32.79 | H5: 1212 | J5: kurang | K5: =+L5/55 -> 0.50163636 | L5: 27.59 | M5: 1523 | O5: baik | P5: =+Q5/$Q$6 -> 0.10674157 | Q5: =+COUNT(AH162:AH180) -> 19 | S5: =+O5 -> baik | T5: 0.1 | U5: =+SUM(AF162:AF180) -> 20149 | V5: 3 | W5: 1370 | X5: 15 | Y5: 7.23 | Z5: 11.72 | AA5: 4.18 | AB5: 7.75 | AC5: =+SUM(X5:AB5) -> 45.88 | AE5: 3 | AF5: 1232 | AG5: 24 | AH5: =+AG5/55*100 -> 43.636364 | AI5: jelek
B6: 13.53 | C6: 6 | D6: 6.5 | E6: 3.1 | F6: 3 | G6: =+SUM(B6:F6) -> 32.13 | H6: 20 | J6: kurang | K6: =+L6/55 -> 0.50927273 | L6: 28.01 | M6: 296 | P6: =SUM(P3:P5) -> 1 | Q6: =SUM(Q3:Q5) -> 178 | T6: =SUM(T3:T5) -> 1 | U6: =SUM(U3:U5) -> 167128 | V6: 4 | W6: 1787 | X6: 12.78 | Y6: 4.14 | Z6: 7.22 | AA6: 2.9 | AB6: 4.96 | AC6: =+SUM(X6:AB6) -> 32 | AE6: 4 | AF6: 455 | AG6: 25.26 | AH6: =+AG6/55*100 -> 45.927273 | AI6: jelek
B7: 12.71 | C7: 4.6 | D7: 10.28 | E7: 2.98 | F7: 4.2 | G7: =+SUM(B7:F7) -> 34.77 | H7: 527 | J7: kurang | K7: =+L7/55 -> 0.51763636 | L7: 28.47 | M7: 971 | V7: 5 | W7: 1096 | X7: 13 | Y7: 6.15 | Z7: 9.64 | AA7: 3.8 | AB7: 7 | AC7: =+SUM(X7:AB7) -> 39.59 | AE7: 5 | AF7: 1613 | AG7: 25.89 | AH7: =+AG7/55*100 -> 47.072727 | AI7: jelek
B8: 13.65 | C8: 3.9 | D8: 8.26 | E8: 3.1 | F8: 6.3 | G8: =+SUM(B8:F8) -> 35.21 | H8: 457 | J8: kurang | K8: =+L8/55 -> 0.51945455 | L8: 28.57 | M8: 2462 | V8: 6 | W8: 1727 | X8: 13.2 | Y8: 5.14 | Z8: 9.13 | AA8: 3.33 | AB8: 5.7 | AC8: =+SUM(X8:AB8) -> 36.5 | AE8: 6 | AF8: 876 | AG8: 26.13 | AH8: =+AG8/55*100 -> 47.509091 | AI8: jelek
B9: 13.38 | C9: 6 | D9: 6.5 | E9: 3.1 | F9: 3 | G9: =+SUM(B9:F9) -> 31.98 | H9: 107 | J9: kurang | K9: =+L9/55 -> 0.53272727 | L9: 29.3 | M9: 193 | V9: 7 | W9: 1378 | X9: 9 | Y9: 8.05 | Z9: 11.19 | AA9: 3.5 | AB9: 7 | AC9: =+SUM(X9:AB9) -> 38.74 | AE9: 7 | AF9: 1523 | AG9: 27.41 | AH9: =+AG9/55*100 -> 49.836364 | AI9: jelek
B10: 14.35 | C10: 4.6 | D10: 7.7 | E10: 3.1 | F10: 3 | G10: =+SUM(B10:F10) -> 32.75 | H10: 39 | J10: kurang | K10: =+L10/55 -> 0.536 | L10: 29.48 | M10: 2946 | V10: 8 | W10: 1763 | X10: 14.47 | Y10: 6.5 | Z10: 8 | AA10: 3.3 | AB10: 6.6 | AC10: =+SUM(X10:AB10) -> 38.87 | AE10: 8 | AF10: 296 | AG10: 28.01 | AH10: =+AG10/55*100 -> 50.927273 | AI10: jelek
B11: 13.54 | C11: 3.8 | D11: 9.7 | E11: 2.9 | F11: 3 | G11: =+SUM(B11:F11) -> 32.94 | H11: 282 | J11: kurang | K11: =+L11/55 -> 0.544 | L11: 29.92 | M11: 1807 | V11: 9 | W11: 1637 | X11: 12.5 | Y11: 7.29 | Z11: 11.49 | AA11: 4.03 | AB11: 7.68 | AC11: =+SUM(X11:AB11) -> 42.99 | AE11: 9 | AF11: 64 | AG11: 28.4 | AH11: =+AG11/55*100 -> 51.636364 | AI11: jelek
B12: 13.27 | C12: 5.9 | D12: 6.5 | E12: 3.1 | F12: 3 | G12: =+SUM(B12:F12) -> 31.77 | H12: 726 | J12: kurang | K12: =+L12/55 -> 0.54636364 | L12: 30.05 | M12: 2581 | V12: 10 | W12: 1086 | X12: 13.42 | Y12: 7.71 | Z12: 11.42 | AA12: 3.88 | AB12: 7.39 | AC12: =+SUM(X12:AB12) -> 43.82 | AE12: 10 | AF12: 971 | AG12: 28.47 | AH12: =+AG12/55*100 -> 51.763636 | AI12: jelek
B13: 13.46 | C13: 6 | D13: 6.5 | E13: 3.1 | F13: 3 | G13: =+SUM(B13:F13) -> 32.06 | H13: 63 | J13: kurang | K13: =+L13/55 -> 0.56054545 | L13: 30.83 | M13: 515 | V13: 11 | W13: 1094 | X13: 10.7 | Y13: 7 | Z13: 10.5 | AA13: 3.5 | AB13: 7 | AC13: =+SUM(X13:AB13) -> 38.7 | AE13: 11 | AF13: 20 | AG13: 29 | AH13: =+AG13/55*100 -> 52.727273 | AI13: jelek
B14: 15 | C14: 5 | D14: 7.14 | E14: 3.1 | F14: 3 | G14: =+SUM(B14:F14) -> 33.24 | H14: 70 | J14: kurang | K14: =+L14/55 -> 0.56181818 | L14: 30.9 | M14: 1470 | V14: 12 | W14: 1867 | X14: 11.6 | Y14: 8.5 | Z14: 12.75 | AA14: 4.25 | AB14: 8.5 | AC14: =+SUM(X14:AB14) -> 45.6 | AE14: 12 | AF14: 193 | AG14: 29.3 | AH14: =+AG14/55*100 -> 53.272727 | AI14: jelek
B15: 14.81 | C15: 6.2 | D15: 9.88 | E15: 2.7 | F15: 4.16 | G15: =+SUM(B15:F15) -> 37.75 | H15: 53 | J15: kurang | K15: =+L15/55 -> 0.56454545 | L15: 31.05 | M15: 1736 | V15: 13 | W15: 1088 | X15: 14.86 | Y15: 7.7 | Z15: 11.15 | AA15: 3.95 | AB15: 7.8 | AC15: =+SUM(X15:AB15) -> 45.46 | AE15: 13 | AF15: 515 | AG15: 29.36 | AH15: =+AG15/55*100 -> 53.381818 | AI15: jelek
B16: 11.04 | C16: 6.95 | D16: 7.86 | E16: 3.45 | F16: 0 | G16: =+SUM(B16:F16) -> 29.3 | H16: 193 | J16: kurang | K16: =+L16/55 -> 0.56490909 | L16: 31.07 | M16: 293 | V16: 14 | W16: 1920 | X16: 13 | Y16: 7.86 | Z16: 11.36 | AA16: 3.95 | AB16: 7 | AC16: =+SUM(X16:AB16) -> 43.17 | AE16: 14 | AF16: 1807 | AG16: 30.22 | AH16: =+AG16/55*100 -> 54.945455 | AI16: jelek
B17: 11.42 | C17: 4.24 | D17: 6.1 | E17: 3.5 | F17: 0 | G17: =+SUM(B17:F17) -> 25.26 | H17: 455 | J17: kurang | K17: =+L17/55 -> 0.56563636 | L17: 31.11 | M17: 1909 | V17: 15 | W17: 1262 | X17: 13.36 | Y17: 7.88 | Z17: 12.03 | AA17: 4.03 | AB17: 7.62 | AC17: =+SUM(X17:AB17) -> 44.92 | AE17: 15 | AF17: 463 | AG17: 30.29 | AH17: =+AG17/55*100 -> 55.072727 | AI17: jelek
B18: 13.4 | C18: 6 | D18: 6.9 | E18: 3.1 | F18: 3 | G18: =+SUM(B18:F18) -> 32.4 | H18: 16 | J18: kurang | K18: =+L18/55 -> 0.56981818 | L18: 31.34 | M18: 1926 | V18: 16 | W18: 2188 | X18: 13.02 | Y18: 7.77 | Z18: 11.61 | AA18: 3.95 | AB18: 7 | AC18: =+SUM(X18:AB18) -> 43.35 | AE18: 16 | AF18: 1470 | AG18: 30.9 | AH18: =+AG18/55*100 -> 56.181818 | AI18: jelek
... B160: 12.38 | C160: 4.4 | D160: 7.46 | E160: 3.73 | F160: 5.8 | G160: =+SUM(B160:F160) -> 33.77 | H160: 1424 | J160: baik | K160: =+L160/55 -> 0.888 | L160: 48.84 | M160: 63 | V160: 158 | W160: 309 | X160: 14.97 | Y160: 6.31 | Z160: 13.15 | AA160: 4.25 | AB160: 7.46 | AC160: =+SUM(X160:AB160) -> 46.14 | AE160: 158 | AF160: 113 | AG160: 43.89 | AH160: =+AG160/55*100 -> 79.8 | AI160: sedang
V161: 159 | W161: 350 | X161: 4.95 | Y161: 7.66 | Z161: 12.75 | AA161: 4.25 | AB161: 8.41 | AC161: =+SUM(X161:AB161) -> 38.02 | AE161: 159 | AF161: 1921 | AG161: 43.89 | AH161: =+AG161/55*100 -> 79.8 | AI161: sedang
V162: 160 | W162: 63 | X162: 14.94 | Y162: 8.7 | Z162: 12.75 | AA162: 4.75 | AB162: 7.7 | AC162: =+SUM(X162:AB162) -> 48.84 | AE162: 160 | AF162: 1182 | AG162: 44 | AH162: =+AG162/55*100 -> 80 | AI162: baik
V163: 161 | W163: 777 | X163: 11.01 | Y163: 6 | Z163: 12.12 | AA163: 3.4 | AB163: 6.35 | AC163: =+SUM(X163:AB163) -> 38.88 | AE163: 161 | AF163: 1151 | AG163: 44.26 | AH163: =+AG163/55*100 -> 80.472727 | AI163: baik
V164: 162 | W164: 80 | X164: 5.29 | Y164: 3.8 | Z164: 12.75 | AA164: 4.25 | AB164: 6.7 | AC164: =+SUM(X164:AB164) -> 32.79 | AE164: 162 | AF164: 1812 | AG164: 44.42 | AH164: =+AG164/55*100 -> 80.763636 | AI164: baik
V165: 163 | W165: 190 | X165: 14.63 | Y165: 4.3 | Z165: 9.3 | AA165: 3.5 | AB165: 3 | AC165: =+SUM(X165:AB165) -> 34.73 | AE165: 163 | AF165: 13 | AG165: 44.46 | AH165: =+AG165/55*100 -> 80.836364 | AI165: baik
V166: 164 | W166: 151 | X166: 13.64 | Y166: 7 | Z166: 10.5 | AA166: 3.5 | AB166: 3 | AC166: =+SUM(X166:AB166) -> 37.64 | AE166: 164 | AF166: 1262 | AG166: 44.92 | AH166: =+AG166/55*100 -> 81.672727 | AI166: baik
V167: 165 | W167: 62 | X167: 12.99 | Y167: 7.41 | Z167: 12.75 | AA167: 3.95 | AB167: 3 | AC167: =+SUM(X167:AB167) -> 40.1 | AE167: 165 | AF167: 1393 | AG167: 44.97 | AH167: =+AG167/55*100 -> 81.763636 | AI167: baik
V168: 166 | W168: 696 | X168: 14.5 | Y168: 7.41 | Z168: 4.5 | AA168: 1.5 | AB168: 8.5 | AC168: =+SUM(X168:AB168) -> 36.41 | AE168: 166 | AF168: 1403 | AG168: 45.31 | AH168: =+AG168/55*100 -> 82.381818 | AI168: baik
V169: 167 | W169: 598 | X169: 14.38 | Y169: 7.41 | Z169: 12.75 | AA169: 4.25 | AB169: 8.5 | AC169: =+SUM(X169:AB169) -> 47.29 | AE169: 167 | AF169: 332 | AG169: 45.36 | AH169: =+AG169/55*100 -> 82.472727 | AI169: baik
V170: 168 | W170: 445 | X170: 14.63 | Y170: 7.41 | Z170: 12.45 | AA170: 3.5 | AB170: 8.5 | AC170: =+SUM(X170:AB170) -> 46.49 | AE170: 168 | AF170: 1239 | AG170: 45.42 | AH170: =+AG170/55*100 -> 82.581818 | AI170: baik
V171: 169 | W171: 64 | X171: 14.1 | Y171: 4.1 | Z171: 4.5 | AA171: 2.7 | AB171: 3 | AC171: =+SUM(X171:AB171) -> 28.4 | AE171: 169 | AF171: 1088 | AG171: 45.46 | AH171: =+AG171/55*100 -> 82.654545 | AI171: baik
V172: 170 | W172: 695 | X172: 14.96 | Y172: 6.88 | Z172: 9.68 | AA172: 2.9 | AB172: 6.1 | AC172: =+SUM(X172:AB172) -> 40.52 | AE172: 170 | AF172: 1867 | AG172: 45.6 | AH172: =+AG172/55*100 -> 82.909091 | AI172: baik
... V180: 178 | W180: 1372 | X180: 8.18 | Y180: 7 | Z180: 12.63 | AA180: 3.5 | AB180: 7 | AC180: =+SUM(X180:AB180) -> 38.31 | AE180: 178 | AF180: 63 | AG180: 48.84 | AH180: =+AG180/55*100 -> 88.8 | AI180: baik

Sheet IKSI
A1: kondisi | B1: Luas | C1: IKSI | F1: kondisi | G1: jumlah D.I | H1: jumlah D.I | K1: kondisi | L1: luas D.I | M1: luas D.I
A2: jelek | B2: 1120 | C2: 47.994 | F2: jelek | G2: =+H2/$H$6 -> 0.12359551 | H2: =+COUNT(AQ3:AQ24) -> 22 | K2: jelek | L2: 0.14 | M2: =+SUM(AP3:AP24) -> 16165 | AC2: No | AD2: DI | AE2: Luas | AF2: fisik | AG2: =+'Non fisik'!X2 -> Produktivitas | AH2: =+'Non fisik'!Y2 -> Sarana Penujang | AI2: =+'Non fisik'!Z2 -> Organisasi Personalia | AJ2: =+'Non fisik'!AA2 -> Dokumentasi | AK2: =+'Non fisik'!AB2 -> P3A/GP3A/IP3A | AL2: IKSI | AN2: No | AO2: DI | AP2: luas | AQ2: IKSI
A3: jelek | B3: 50 | C3: 48.53 | F3: kurang | G3: =+H3/$H$6 -> 0.66292135 | H3: =+COUNT(AQ25:AQ142) -> 118 | K3: kurang | L3: 0.72 | M3: =+SUM(AP25:AP142) -> 102710 | AC3: 1 | AD3: D.I. CEPOGO | AE3: 1000 | AF3: 30 | AG3: 9.63 | AH3: 7.23 | AI3: 11.72 | AJ3: 4.18 | AK3: 7 | AL3: =+SUM(AF3:AK3) -> 69.76 | AN3: 1 | AO3: D.I. RANUGRATI | AP3: 1085 | AQ3: 39.17 | AR3: jelek
A4: jelek | B4: 1008 | C4: 51.07 | F4: baik | G4: =+H4/$H$6 -> 0.21348315 | H4: =+COUNT(AQ143:AQ180) -> 38 | K4: baik | L4: 0.11 | M4: =+SUM(AP143:AP180) -> 48253 | AC4: 2 | AD4: D.I. DALEM | AE4: 1403 | AF4: 21.53 | AG4: 14.91 | AH4: 8.5 | AI4: 11.1 | AJ4: 4.25 | AK4: 6.55 | AL4: =+SUM(AF4:AK4) -> 66.84 | AN4: 2 | AO4: D.I. WD. GOGOR | AP4: 1054 | AQ4: 44.4 | AR4: jelek
A5: jelek | B5: 2340 | C5: 51.19 | AC5: 3 | AD5: D.I. SAMPUNG | AE5: 1370 | AF5: 30.94 | AG5: 15 | AH5: 7.23 | AI5: 11.72 | AJ5: 4.18 | AK5: 7.75 | AL5: =+SUM(AF5:AK5) -> 76.82 | AN5: 3 | AO5: D.I. SUMBER BERJO | AP5: 45 | AQ5: 44.81 | AR5: jelek
A6: jelek | B6: 194 | C6: 51.4 | G6: =SUM(G2:G5) -> 1 | H6: =SUM(H2:H5) -> 178 | L6: =SUM(L2:L5) -> 0.97 | M6: =SUM(M2:M5) -> 167128 | AC6: 4 | AD6: D.I. SUMOROBANGUN | AE6: 1787 | AF6: 27.97 | AG6: 12.78 | AH6: 4.14 | AI6: 7.22 | AJ6: 2.9 | AK6: 4.96 | AL6: =+SUM(AF6:AK6) -> 59.97 | AN6: 4 | AO6: D.I. TELEBUK | AP6: 1132 | AQ6: 45.2 | AR6: jelek
A7: jelek | B7: 1232 | C7: 51.63 | AC7: 5 | AD7: D.I. WATU PUTIH | AE7: 1096 | AF7: 25.69 | AG7: 13 | AH7: 6.15 | AI7: 9.64 | AJ7: 3.8 | AK7: 7 | AL7: =+SUM(AF7:AK7) -> 65.28 | AN7: 5 | AO7: D.I. KALIGERMAN | AP7: 1120 | AQ7: 47.99 | AR7: jelek
A8: jelek | B8: 1085 | C8: 51.64 | AC8: 6 | AD8: D.I. WILANGAN | AE8: 1727 | AF8: 29.38 | AG8: 13.2 | AH8: 5.14 | AI8: 9.13 | AJ8: 3.33 | AK8: 5.7 | AL8: =+SUM(AF8:AK8) -> 65.88 | AN8: 6 | AO8: D.I. MERAK URAK | AP8: 1475 | AQ8: 48.47 | AR8: jelek
A9: jelek | B9: 1055 | C9: 52.18 | AC9: 7 | AD9: D.I. GELANG | AE9: 1378 | AF9: 23.96 | AG9: 9 | AH9: 8.05 | AI9: 11.19 | AJ9: 3.5 | AK9: 7 | AL9: =+SUM(AF9:AK9) -> 62.7 | AN9: 7 | AO9: D.I. MOJOPURNO | AP9: 50 | AQ9: 48.53 | AR9: jelek
A10: jelek | B10: 209 | C10: 52.18 | AC10: 8 | AD10: D.I. DERMEN | AE10: 1763 | AF10: 33.18 | AG10: 14.47 | AH10: 6.5 | AI10: 8 | AJ10: 3.3 | AK10: 6.6 | AL10: =+SUM(AF10:AK10) -> 72.05 | AN10: 8 | AO10: D.I. KALI WADAK | AP10: 1476 | AQ10: 49.22 | AR10: jelek
A11: jelek | B11: 1799 | C11: 52.22 | AC11: 9 | AD11: D.I. KETANDAN | AE11: 1637 | AF11: 32 | AG11: 12.5 | AH11: 7.29 | AI11: 11.49 | AJ11: 4.03 | AK11: 7.68 | AL11: =+SUM(AF11:AK11) -> 74.99 | AN11: 9 | AO11: D.I. LONTONG | AP11: 151 | AQ11: 49.69 | AR11: jelek
A12: jelek | B12: 461 | C12: 52.57 | AC12: 10 | AD12: D.I. POHBLEMBEM | AE12: 1086 | AF12: 30 | AG12: 13.42 | AH12: 7.71 | AI12: 11.42 | AJ12: 3.88 | AK12: 7.39 | AL12: =+SUM(AF12:AK12) -> 73.82 | AN12: 10 | AO12: D.I. KEMBANGAN | AP12: 281 | AQ12: 50.43 | AR12: jelek
A13: jelek | B13: 455 | C13: 53.14 | AC13: 11 | AD13: D.I. BRUG PURWO | AE13: 1094 | AF13: 32.12 | AG13: 10.7 | AH13: 7 | AI13: 10.5 | AJ13: 3.5 | AK13: 7 | AL13: =+SUM(AF13:AK13) -> 70.82 | AN13: 11 | AO13: D.I. CAU | AP13: 1232 | AQ13: 51.63 | AR13: jelek
A14: jelek | B14: 971 | C14: 53.15 | AC14: 12 | AD14: D.I. CURAH MENJANGAN/KEDUNGSANGKU | AE14: 1867 | AF14: 33.12 | AG14: 11.6 | AH14: 8.5 | AI14: 12.75 | AJ14: 4.25 | AK14: 8.5 | AL14: =+SUM(AF14:AK14) -> 78.72 | AN14: 12 | AO14: D.I. KULUHAN | AP14: 209 | AQ14: 52.18 | AR14: jelek
A15: jelek | B15: 1779 | C15: 53.22 | AC15: 13 | AD15: D.I. JURANG DAWIR | AE15: 1088 | AF15: 21.64 | AG15: 14.86 | AH15: 7.7 | AI15: 11.15 | AJ15: 3.95 | AK15: 7.8 | AL15: =+SUM(AF15:AK15) -> 67.1 | AN15: 13 | AO15: D.I. SURAK | AP15: 876 | AQ15: 52.26 | AR15: jelek
A16: jelek | B16: 629 | C16: 53.59 | AC16: 14 | AD16: D.I. TEKUNG I | AE16: 1920 | AF16: 22.26 | AG16: 13 | AH16: 7.86 | AI16: 11.36 | AJ16: 3.95 | AK16: 7 | AL16: =+SUM(AF16:AK16) -> 65.43 | AN16: 14 | AO16: D.I. SENGKALING KIRI | AP16: 455 | AQ16: 53.14 | AR16: jelek
A17: jelek | B17: 59 | C17: 53.64 | AC17: 15 | AD17: D.I. UMBUL PRINGTALI | AE17: 1262 | AF17: 23.34 | AG17: 13.36 | AH17: 7.88 | AI17: 12.03 | AJ17: 4.03 | AK17: 7.62 | AL17: =+SUM(AF17:AK17) -> 68.26 | AN17: 15 | AO17: D.I. RAWA SEKARAN | AP17: 1779 | AQ17: 53.22 | AR17: jelek
A18: jelek | B18: 551 | C18: 53.71 | AC18: 16 | AD18: D.I. BAGO | AE18: 2188 | AF18: 30.37 | AG18: 13.02 | AH18: 7.77 | AI18: 11.61 | AJ18: 3.95 | AK18: 7 | AL18: =+SUM(AF18:AK18) -> 73.72 | AN18: 16 | AO18: D.I. KLALUNG | AP18: 629 | AQ18: 53.59 | AR18: jelek
... A159: sangat baik | B159: 1393 | C159: 83.09 | AC159: 157 | AD159: D.I. ARJASA | AE159: 319 | AF159: 32.48 | AG159: 13.4 | AH159: 5.06 | AI159: 10.71 | AJ159: 3.5 | AK159: 7.95 | AL159: =+SUM(AF159:AK159) -> 73.1 | AN159: 157 | AO159: D.I. TANGGULANGIN | AP159: 2581 | AQ159: 72.87 | AR159: baik
AC160: 158 | AD160: D.I. NURBIHA | AE160: 309 | AF160: 26.08 | AG160: 14.97 | AH160: 6.31 | AI160: 13.15 | AJ160: 4.25 | AK160: 7.46 | AL160: =+SUM(AF160:AK160) -> 72.22 | AN160: 158 | AO160: D.I. ARJASA | AP160: 319 | AQ160: 73.1 | AR160: baik
AC161: 159 | AD161: D.I. GUMBOLO/DAWUHAN | AE161: 350 | AF161: 19.32 | AG161: 4.95 | AH161: 7.66 | AI161: 12.75 | AJ161: 4.25 | AK161: 8.41 | AL161: =+SUM(AF161:AK161) -> 57.34 | AN161: 159 | AO161: D.I. BULAKMOJO | AP161: 1211 | AQ161: 73.26 | AR161: baik
AC162: 160 | AD162: D.I. PRINGDURI | AE162: 63 | AF162: 24.78 | AG162: 14.94 | AH162: 8.7 | AI162: 12.75 | AJ162: 4.75 | AK162: 7.7 | AL162: =+SUM(AF162:AK162) -> 73.62 | AN162: 160 | AO162: D.I. KEDUNGREJO | AP162: 1554 | AQ162: 73.46 | AR162: baik
AC163: 161 | AD163: D.I. BAJULMATI | AE163: 777 | AF163: 32.61 | AG163: 11.01 | AH163: 6 | AI163: 12.12 | AJ163: 3.4 | AK163: 6.35 | AL163: =+SUM(AF163:AK163) -> 71.49 | AN163: 161 | AO163: D.I. WONOSROYO | AP163: 1499 | AQ163: 73.6 | AR163: baik
AC164: 162 | AD164: D.I. SBR. NYAMPLONG | AE164: 80 | AF164: 32 | AG164: 5.29 | AH164: 3.8 | AI164: 12.75 | AJ164: 4.25 | AK164: 6.7 | AL164: =+SUM(AF164:AK164) -> 64.79 | AN164: 162 | AO164: D.I. PRINGDURI | AP164: 63 | AQ164: 73.62 | AR164: baik
AC165: 163 | AD165: D.I. I.S PAKIS | AE165: 190 | AF165: 26.75 | AG165: 14.63 | AH165: 4.3 | AI165: 9.3 | AJ165: 3.5 | AK165: 3 | AL165: =+SUM(AF165:AK165) -> 61.48 | AN165: 163 | AO165: D.I. BAGO | AP165: 2188 | AQ165: 73.72 | AR165: baik
AC166: 164 | AD166: D.I. LONTONG | AE166: 151 | AF166: 12.05 | AG166: 13.64 | AH166: 7 | AI166: 10.5 | AJ166: 3.5 | AK166: 3 | AL166: =+SUM(AF166:AK166) -> 49.69 | AN166: 164 | AO166: D.I. POHBLEMBEM | AP166: 1086 | AQ166: 73.82 | AR166: baik
AC167: 165 | AD167: D.I. WARUJINGGO | AE167: 62 | AF167: 15.95 | AG167: 12.99 | AH167: 7.41 | AI167: 12.75 | AJ167: 3.95 | AK167: 3 | AL167: =+SUM(AF167:AK167) -> 56.05 | AN167: 165 | AO167: D.I. KLITIK BENDOKROSOK | AP167: 332 | AQ167: 74.88 | AR167: baik
AC168: 166 | AD168: D.I. TAPOSAN | AE168: 696 | AF168: 29.64 | AG168: 14.5 | AH168: 7.41 | AI168: 4.5 | AJ168: 1.5 | AK168: 8.5 | AL168: =+SUM(AF168:AK168) -> 66.05 | AN168: 166 | AO168: D.I. KETANDAN | AP168: 1637 | AQ168: 74.99 | AR168: baik
AC169: 167 | AD169: D.I. KRASAK | AE169: 598 | AF169: 27.75 | AG169: 14.38 | AH169: 7.41 | AI169: 12.75 | AJ169: 4.25 | AK169: 8.5 | AL169: =+SUM(AF169:AK169) -> 75.04 | AN169: 167 | AO169: D.I. KRASAK | AP169: 598 | AQ169: 75.04 | AR169: baik
AC170: 168 | AD170: D.I. MBOK SITI | AE170: 445 | AF170: 30.65 | AG170: 14.63 | AH170: 7.41 | AI170: 12.45 | AJ170: 3.5 | AK170: 8.5 | AL170: =+SUM(AF170:AK170) -> 77.14 | AN170: 168 | AO170: D.I. JATIMLEREK | AP170: 1812 | AQ170: 75.22 | AR170: baik
AC171: 169 | AD171: D.I. BANGO | AE171: 64 | AF171: 28.94 | AG171: 14.1 | AH171: 4.1 | AI171: 4.5 | AJ171: 2.7 | AK171: 3 | AL171: =+SUM(AF171:AK171) -> 57.34 | AN171: 169 | AO171: D.I. GROGOL | AP171: 1239 | AQ171: 75.42 | AR171: baik
... AC180: 178 | AD180: D.I. WIDODAREN | AE180: 1372 | AF180: 21.51 | AG180: 8.18 | AH180: 7 | AI180: 12.63 | AJ180: 3.5 | AK180: 7 | AL180: =+SUM(AF180:AK180) -> 59.82 | AN180: 178 | AO180: D.I. KOTTOK | AP180: 1879 | AQ180: 79.74 | AR180: baik

Sheet average
C1: Komponen | D1: Yang Ada | E1: Maks | F1: Min | G1: Optimum
C2: Prasarana Fisik | D2: =+AI181 -> 28.13207 | E2: 45 | F2: 25 | G2: 35 | X2: No | Y2: DI | Z2: Luas | AA2: fisik | AB2: Produktivitas | AC2: Sarana Penujang | AD2: Organisasi Personalia | AE2: Dokumentasi | AF2: P3A/GP3A/IP3A | AG2: IKSI | AI2: fisik | AJ2: Produktivitas | AK2: Sarana Penujang | AL2: Organisasi Personalia | AM2: Dokumentasi | AN2: P3A/GP3A/IP3A
C3: Produktivitas | D3: =+AJ181 -> 11.854102 | E3: 15 | F3: 10 | G3: 12.5 | X3: 1 | Y3: D.I. CEPOGO | Z3: 1000 | AA3: 30 | AB3: 9.63 | AC3: 7.23 | AD3: 11.72 | AE3: 4.18 | AF3: 7 | AG3: 69.76 | AI3: =+AA3*Z3/$Z$181 -> 0.17950314 | AJ3: =+AB3*Z3/$Z$181 -> 0.057620506 | AK3: =+AC3*Z3/$Z$181 -> 0.043260256 | AL3: =+AD3*Z3/$Z$181 -> 0.070125892 | AM3: =+AE3*Z3/$Z$181 -> 0.02501077 | AN3: =+AF3*Z3/$Z$181 -> 0.041884065
C4: Sarana Penujang | D4: =+AK181 -> 6.2055456 | E4: 10 | F4: 5 | G4: 7.5 | X4: 2 | Y4: D.I. DALEM | Z4: 1403 | AA4: 21.53 | AB4: 14.91 | AC4: 8.5 | AD4: 11.1 | AE4: 4.25 | AF4: 6.55 | AG4: 66.84 | AI4: =+AA4*Z4/$Z$181 -> 0.18073925 | AJ4: =+AB4*Z4/$Z$181 -> 0.12516592 | AK4: =+AC4*Z4/$Z$181 -> 0.071355488 | AL4: =+AD4*Z4/$Z$181 -> 0.093181873 | AM4: =+AE4*Z4/$Z$181 -> 0.035677744 | AN4: =+AF4*Z4/$Z$181 -> 0.0549857
C5: Organisasi Personalia | D5: =+AL181 -> 9.9658699 | E5: 15 | F5: 7.5 | G5: 10 | X5: 3 | Y5: D.I. SAMPUNG | Z5: 1370 | AA5: 30.94 | AB5: 15 | AC5: 7.23 | AD5: 11.72 | AE5: 4.18 | AF5: 7.75 | AG5: 76.82 | AI5: =+AA5*Z5/$Z$181 -> 0.25362477 | AJ5: =+AB5*Z5/$Z$181 -> 0.12295965 | AK5: =+AC5*Z5/$Z$181 -> 0.05926655 | AL5: =+AD5*Z5/$Z$181 -> 0.096072471 | AM5: =+AE5*Z5/$Z$181 -> 0.034264755 | AN5: =+AF5*Z5/$Z$181 -> 0.063529151
C6: Dokumentasi | D6: =+AM181 -> 3.4962514 | E6: 5 | F6: 2.5 | G6: 5 | X6: 4 | Y6: D.I. SUMOROBANGUN | Z6: 1787 | AA6: 27.97 | AB6: 12.78 | AC6: 4.14 | AD6: 7.22 | AE6: 2.9 | AF6: 4.96 | AG6: 59.97 | AI6: =+AA6*Z6/$Z$181 -> 0.29906652 | AJ6: =+AB6*Z6/$Z$181 -> 0.13664892 | AK6: =+AC6*Z6/$Z$181 -> 0.04426655 | AL6: =+AD6*Z6/$Z$181 -> 0.077199153 | AM6: =+AE6*Z6/$Z$181 -> 0.03100797 | AN6: =+AF6*Z6/$Z$181 -> 0.053034321
C7: P3A/GP3A/IP3A | D7: =+AN181 -> 6.1105784 | E7: 10 | F7: 5 | G7: 7.5 | X7: 5 | Y7: D.I. WATU PUTIH | Z7: 1096 | AA7: 25.69 | AB7: 13 | AC7: 6.15 | AD7: 9.64 | AE7: 3.8 | AF7: 7 | AG7: 65.28 | AI7: =+AA7*Z7/$Z$181 -> 0.16847111 | AJ7: =+AB7*Z7/$Z$181 -> 0.085252022 | AK7: =+AC7*Z7/$Z$181 -> 0.040330764 | AL7: =+AD7*Z7/$Z$181 -> 0.063217654 | AM7: =+AE7*Z7/$Z$181 -> 0.024919822 | AN7: =+AF7*Z7/$Z$181 -> 0.045904935
C8: Jumlah IKSI | D8: =SUM(D2:D7) -> 65.764417 | E8: =SUM(E2:E7) -> 100 | F8: =SUM(F2:F7) -> 55 | G8: =SUM(G2:G7) -> 77.5 | X8: 6 | Y8: D.I. WILANGAN | Z8: 1727 | AA8: 29.38 | AB8: 13.2 | AC8: 5.14 | AD8: 9.13 | AE8: 3.33 | AF8: 5.7 | AG8: 65.88 | AI8: =+AA8*Z8/$Z$181 -> 0.30359521 | AJ8: =+AB8*Z8/$Z$181 -> 0.13640084 | AK8: =+AC8*Z8/$Z$181 -> 0.053113661 | AL8: =+AD8*Z8/$Z$181 -> 0.094343916 | AM8: =+AE8*Z8/$Z$181 -> 0.034410213 | AN8: =+AF8*Z8/$Z$181 -> 0.058900364
X9: 7 | Y9: D.I. GELANG | Z9: 1378 | AA9: 23.96 | AB9: 9 | AC9: 8.05 | AD9: 11.19 | AE9: 3.5 | AF9: 7 | AG9: 62.7 | AI9: =+AA9*Z9/$Z$181 -> 0.19755445 | AJ9: =+AB9*Z9/$Z$181 -> 0.074206596 | AK9: =+AC9*Z9/$Z$181 -> 0.066373678 | AL9: =+AD9*Z9/$Z$181 -> 0.092263535 | AM9: =+AE9*Z9/$Z$181 -> 0.028858121 | AN9: =+AF9*Z9/$Z$181 -> 0.057716241
X10: 8 | Y10: D.I. DERMEN | Z10: 1763 | AA10: 33.18 | AB10: 14.47 | AC10: 6.5 | AD10: 8 | AE10: 3.3 | AF10: 6.6 | AG10: 72.05 | AI10: =+AA10*Z10/$Z$181 -> 0.35000921 | AJ10: =+AB10*Z10/$Z$181 -> 0.15264115 | AK10: =+AC10*Z10/$Z$181 -> 0.068567206 | AL10: =+AD10*Z10/$Z$181 -> 0.084390407 | AM10: =+AE10*Z10/$Z$181 -> 0.034811043 | AN10: =+AF10*Z10/$Z$181 -> 0.069622086
X11: 9 | Y11: D.I. KETANDAN | Z11: 1637 | AA11: 32 | AB11: 12.5 | AC11: 7.29 | AD11: 11.49 | AE11: 4.03 | AF11: 7.68 | AG11: 74.99 | AI11: =+AA11*Z11/$Z$181 -> 0.31343641 | AJ11: =+AB11*Z11/$Z$181 -> 0.1224361 | AK11: =+AC11*Z11/$Z$181 -> 0.071404732 | AL11: =+AD11*Z11/$Z$181 -> 0.11254326 | AM11: =+AE11*Z11/$Z$181 -> 0.039473398 | AN11: =+AF11*Z11/$Z$181 -> 0.075224738
X12: 10 | Y12: D.I. POHBLEMBEM | Z12: 1086 | AA12: 30 | AB12: 13.42 | AC12: 7.71 | AD12: 11.42 | AE12: 3.88 | AF12: 7.39 | AG12: 73.82 | AI12: =+AA12*Z12/$Z$181 -> 0.1949404 | AJ12: =+AB12*Z12/$Z$181 -> 0.087203341 | AK12: =+AC12*Z12/$Z$181 -> 0.050099684 | AL12: =+AD12*Z12/$Z$181 -> 0.074207314 | AM12: =+AE12*Z12/$Z$181 -> 0.025212292 | AN12: =+AF12*Z12/$Z$181 -> 0.04802032
X13: 11 | Y13: D.I. BRUG PURWO | Z13: 1094 | AA13: 32.12 | AB13: 10.7 | AC13: 7 | AD13: 10.5 | AE13: 3.5 | AF13: 7 | AG13: 70.82 | AI13: =+AA13*Z13/$Z$181 -> 0.2102537 | AJ13: =+AB13*Z13/$Z$181 -> 0.070040927 | AK13: =+AC13*Z13/$Z$181 -> 0.045821167 | AL13: =+AD13*Z13/$Z$181 -> 0.068731751 | AM13: =+AE13*Z13/$Z$181 -> 0.022910584 | AN13: =+AF13*Z13/$Z$181 -> 0.045821167
X14: 12 | Y14: D.I. CURAH MENJANGAN/KEDUNGSANGKU | Z14: 1867 | AA14: 33.12 | AB14: 11.6 | AC14: 8.5 | AD14: 12.75 | AE14: 4.25 | AF14: 8.5 | AG14: 78.72 | AI14: =+AA14*Z14/$Z$181 -> 0.36998612 | AJ14: =+AB14*Z14/$Z$181 -> 0.12958451 | AK14: =+AC14*Z14/$Z$181 -> 0.094954167 | AL14: =+AD14*Z14/$Z$181 -> 0.14243125 | AM14: =+AE14*Z14/$Z$181 -> 0.047477083 | AN14: =+AF14*Z14/$Z$181 -> 0.094954167
X15: 13 | Y15: D.I. JURANG DAWIR | Z15: 1088 | AA15: 21.64 | AB15: 14.86 | AC15: 7.7 | AD15: 11.15 | AE15: 3.95 | AF15: 7.8 | AG15: 67.1 | AI15: =+AA15*Z15/$Z$181 -> 0.14087598 | AJ15: =+AB15*Z15/$Z$181 -> 0.096738308 | AK15: =+AC15*Z15/$Z$181 -> 0.050126849 | AL15: =+AD15*Z15/$Z$181 -> 0.072586281 | AM15: =+AE15*Z15/$Z$181 -> 0.025714422 | AN15: =+AF15*Z15/$Z$181 -> 0.050777847
X16: 14 | Y16: D.I. TEKUNG I | Z16: 1920 | AA16: 22.26 | AB16: 13 | AC16: 7.86 | AD16: 11.36 | AE16: 3.95 | AF16: 7 | AG16: 65.43 | AI16: =+AA16*Z16/$Z$181 -> 0.25572735 | AJ16: =+AB16*Z16/$Z$181 -> 0.14934661 | AK16: =+AC16*Z16/$Z$181 -> 0.090297257 | AL16: =+AD16*Z16/$Z$181 -> 0.13050596 | AM16: =+AE16*Z16/$Z$181 -> 0.045378393 | AN16: =+AF16*Z16/$Z$181 -> 0.080417405
X17: 15 | Y17: D.I. UMBUL PRINGTALI | Z17: 1262 | AA17: 23.34 | AB17: 13.36 | AC17: 7.88 | AD17: 12.03 | AE17: 4.03 | AF17: 7.62 | AG17: 68.26 | AI17: =+AA17*Z17/$Z$181 -> 0.17624264 | AJ17: =+AB17*Z17/$Z$181 -> 0.10088268 | AK17: =+AC17*Z17/$Z$181 -> 0.059502657 | AL17: =+AD17*Z17/$Z$181 -> 0.090839716 | AM17: =+AE17*Z17/$Z$181 -> 0.030430927 | AN17: =+AF17*Z17/$Z$181 -> 0.057539371
X18: 16 | Y18: D.I. BAGO | Z18: 2188 | AA18: 30.37 | AB18: 13.02 | AC18: 7.77 | AD18: 11.61 | AE18: 3.95 | AF18: 7 | AG18: 73.72 | AI18: =+AA18*Z18/$Z$181 -> 0.39759681 | AJ18: =+AB18*Z18/$Z$181 -> 0.17045474 | AK18: =+AC18*Z18/$Z$181 -> 0.10172299 | AL18: =+AD18*Z18/$Z$181 -> 0.15199536 | AM18: =+AE18*Z18/$Z$181 -> 0.05171246 | AN18: =+AF18*Z18/$Z$181 -> 0.091642334
X19: 17 | Y19: D.I. GROGOL | Z19: 1239 | AA19: 30 | AB19: 14.53 | AC19: 8.05 | AD19: 11.9 | AE19: 3.88 | AF19: 7.06 | AG19: 75.42 | AI19: =+AA19*Z19/$Z$181 -> 0.22240438 | AJ19: =+AB19*Z19/$Z$181 -> 0.10771786 | AK19: =+AC19*Z19/$Z$181 -> 0.05967851 | AL19: =+AD19*Z19/$Z$181 -> 0.088220406 | AM19: =+AE19*Z19/$Z$181 -> 0.0287643 | AN19: =+AF19*Z19/$Z$181 -> 0.052339165
X20: 18 | Y20: D.I. KARANGLO | Z20: 2323 | AA20: 20.18 | AB20: 12.05 | AC20: 7.56 | AD20: 11.37 | AE20: 3.65 | AF20: 8.05 | AG20: 62.86 | AI20: =+AA20*Z20/$Z$181 -> 0.28049244 | AJ20: =+AB20*Z20/$Z$181 -> 0.16748929 | AK20: =+AC20*Z20/$Z$181 -> 0.10508042 | AL20: =+AD20*Z20/$Z$181 -> 0.15803761 | AM20: =+AE20*Z20/$Z$181 -> 0.05073327 | AN20: =+AF20*Z20/$Z$181 -> 0.11189119
... X180: 178 | Y180: D.I. WIDODAREN | Z180: 1372 | AA180: 21.51 | AB180: 8.18 | AC180: 7 | AD180: 12.63 | AE180: 3.5 | AF180: 7 | AG180: 59.82 | AI180: =+AA180*Z180/$Z$181 -> 0.17658154 | AJ180: =+AB180*Z180/$Z$181 -> 0.067151884 | AK180: =+AC180*Z180/$Z$181 -> 0.057464937 | AL180: =+AD180*Z180/$Z$181 -> 0.10368316 | AM180: =+AE180*Z180/$Z$181 -> 0.028732469 | AN180: =+AF180*Z180/$Z$181 -> 0.057464937
Z181: =SUM(Z3:Z180) -> 167128 | AI181: =SUM(AI3:AI180) -> 28.13207 | AJ181: =SUM(AJ3:AJ180) -> 11.854102 | AK181: =SUM(AK3:AK180) -> 6.2055456 | AL181: =SUM(AL3:AL180) -> 9.9658699 | AM181: =SUM(AM3:AM180) -> 3.4962514 | AN181: =SUM(AN3:AN180) -> 6.1105784 | AO181: =+SUM(AI181:AN181) -> 65.764417

Sheet EPAKSI
A1: Daftar User Name Aplikasi EPAKSI Daerah Irigasi Kewenangan Pemerintah Provinsi Jawa Timur
A2: No. | B2: Nomeklatur/ Nama Daerah Irigasi | C2: Luas Daerah Irigasi Sesuai Permen 14/2015 (Ha) | D2: Lokasi Kabupaten/Kota | E2: Kode D.I | F2: Indeks Kondisi Sistem Irigasi (%) | M2: Keterangan | P2: IKSI PER UPT | X2: IKSI SE JAWA TIMUR | AF2: BENDUNG
F3: Prasarana Fisik | G3: Produktivitas | H3: Sarana Penujang | I3: Organisasi Personalia | J3: Dokumentasi | K3: P3A/GP3A/IP3A | L3: Jumlah | P3: Prasarana Fisik | Q3: Produktivitas | R3: Sarana Penujang | S3: Organisasi Personalia | T3: Dokumentasi | U3: P3A/GP3A/IP3A | V3: Jumlah | X3: Prasarana Fisik | Y3: Produktivitas | Z3: Sarana Penujang | AA3: Organisasi Personalia | AB3: Dokumentasi | AC3: P3A/GP3A/IP3A | AD3: Jumlah | AF3: Tahun | AG3: Nilai
F5: Nilai Maks 45% | G5: Nilai Maks 15% | H5: Nilai Maks 10% | I5: Nilai Maks 15% | J5: Nilai Maks 5% | K5: Nilai Maks 10% | L5: Nilai Maks 100% | P5: Nilai Maks 45% | Q5: Nilai Maks 15% | R5: Nilai Maks 10% | S5: Nilai Maks 15% | T5: Nilai Maks 5% | U5: Nilai Maks 10% | V5: Nilai Maks 100% | X5: Nilai Maks 45% | Y5: Nilai Maks 15% | Z5: Nilai Maks 10% | AA5: Nilai Maks 15% | AB5: Nilai Maks 5% | AC5: Nilai Maks 10% | AD5: Nilai Maks 100%
A6: I | B6: UPT PSDA WS Brantas (Korwil Malang)
A7: 1 | B7: D.I. Bakalan | C7: 148 | D7: Kab./Kota Malang | E7: 35000001 | F7: 29.82 | G7: 13.38 | H7: 6 | I7: 6.5 | J7: 3.1 | K7: 3.4 | L7: =+SUM(F7:K7) -> 62.2 | M7: Penilaian prasarana fisik 2022 dan non prasarana fisik 2022 | P7: =(F7*C7)/$C$42 -> 0.45876923 | Q7: =(G7*C7)/$C$42 -> 0.20584615 | R7: =(H7*C7)/$C$42 -> 0.092307692 | S7: =(I7*C7)/$C$42 -> 0.1 | T7: =(J7*C7)/$C$42 -> 0.047692308 | U7: =(K7*C7)/$C$42 -> 0.052307692 | X7: =(F7*C7)/$C$202 -> 0.026407065 | Y7: =(G7*C7)/$C$202 -> 0.011848643 | Z7: =(H7*C7)/$C$202 -> 0.0053132928 | AA7: =(I7*C7)/$C$202 -> 0.0057560672 | AB7: =(J7*C7)/$C$202 -> 0.0027452013 | AC7: =(K7*C7)/$C$202 -> 0.0030108659
A8: 2 | B8: D.I. Bodo | C8: 156 | D8: Kab./Kota Malang | E8: 35000002 | F8: 29.92 | G8: 13.36 | H8: 6 | I8: 6.5 | J8: 3.1 | K8: 3 | L8: =+SUM(F8:K8) -> 61.88 | M8: Penilaian prasarana fisik 2022 dan non prasarana fisik 2022 | P8: =(F8*C8)/$C$42 -> 0.48518919 | Q8: =(G8*C8)/$C$42 -> 0.21664865 | R8: =(H8*C8)/$C$42 -> 0.097297297 | S8: =(I8*C8)/$C$42 -> 0.10540541 | T8: =(J8*C8)/$C$42 -> 0.05027027 | U8: =(K8*C8)/$C$42 -> 0.048648649 | X8: =(F8*C8)/$C$202 -> 0.027927816 | Y8: =(G8*C8)/$C$202 -> 0.012470442 | Z8: =(H8*C8)/$C$202 -> 0.0056004978 | AA8: =(I8*C8)/$C$202 -> 0.006067206 | AB8: =(J8*C8)/$C$202 -> 0.0028935905 | AC8: =(K8*C8)/$C$202 -> 0.0028002489
A9: 3 | B9: D.I. Kadalpang | C9: 1212 | D9: Kab./Kota Malang | E9: 35000003 | F9: 16.71 | G9: 14.34 | H9: 6 | I9: 6.5 | J9: 2.9 | K9: 3.99 | L9: =+SUM(F9:K9) -> 50.44 | M9: Penilaian prasarana fisik 2022 dan non prasarana fisik 2022 | P9: =(F9*C9)/$C$42 -> 2.1052516 | Q9: =(G9*C9)/$C$42 -> 1.8066611 | R9: =(H9*C9)/$C$42 -> 0.75592516 | S9: =(I9*C9)/$C$42 -> 0.81891892 | T9: =(J9*C9)/$C$42 -> 0.36536383 | U9: =(K9*C9)/$C$42 -> 0.50269023 | X9: =(F9*C9)/$C$202 -> 0.12117969 | Y9: =(G9*C9)/$C$202 -> 0.10399263 | Z9: =(H9*C9)/$C$202 -> 0.04351156 | AA9: =(I9*C9)/$C$202 -> 0.047137523 | AB9: =(J9*C9)/$C$202 -> 0.021030587 | AC9: =(K9*C9)/$C$202 -> 0.028935187
A10: 4 | B10: D.I. Kajar II A | C10: 20 | D10: Kab./Kota Malang | E10: 35000004 | F10: 28.65 | G10: 13.53 | H10: 6 | I10: 6.5 | J10: 3.1 | K10: 3.2 | L10: =+SUM(F10:K10) -> 60.98 | M10: Penilaian prasarana fisik 2022 dan non prasarana fisik 2022 | P10: =(F10*C10)/$C$42 -> 0.05956341 | Q10: =(G10*C10)/$C$42 -> 0.028128898 | R10: =(H10*C10)/$C$42 -> 0.012474012 | S10: =(I10*C10)/$C$42 -> 0.013513514 | T10: =(J10*C10)/$C$42 -> 0.0064449064 | U10: =(K10*C10)/$C$42 -> 0.0066528067 | X10: =(F10*C10)/$C$202 -> 0.0034285099 | Y10: =(G10*C10)/$C$202 -> 0.0016191183 | Z10: =(H10*C10)/$C$202 -> 0.00071801254 | AA10: =(I10*C10)/$C$202 -> 0.00077784692 | AB10: =(J10*C10)/$C$202 -> 0.00037097315 | AC10: =(K10*C10)/$C$202 -> 0.00038294002
A11: 5 | B11: D.I. Kali Metro | C11: 527 | D11: Kab./Kota Malang | E11: 35000005 | F11: 28.25 | G11: 12.75 | H11: 4.6 | I11: 10.28 | J11: 2.98 | K11: 4.2 | L11: =+SUM(F11:K11) -> 63.06 | M11: Penilaian prasarana fisik 2023 dan non prasarana fisik 2023 | P11: =(F11*C11)/$C$42 -> 1.5475832 | Q11: =(G11*C11)/$C$42 -> 0.69846674 | R11: =(H11*C11)/$C$42 -> 0.25199584 | S11: =(I11*C11)/$C$42 -> 0.56315593 | T11: =(J11*C11)/$C$42 -> 0.16324948 | U11: =(K11*C11)/$C$42 -> 0.23008316 | X11: =(F11*C11)/$C$202 -> 0.089079927 | Y11: =(G11*C11)/$C$202 -> 0.040204215 | Z11: =(H11*C11)/$C$202 -> 0.01450505 | AA11: =(I11*C11)/$C$202 -> 0.032415634 | AB11: =(J11*C11)/$C$202 -> 0.0093967498 | AC11: =(K11*C11)/$C$202 -> 0.013243741
A12: 6 | B12: D.I. Kalilanang | C12: 457 | D12: Kab. Malang, Kota Batu | E12: 35000006 | F12: 23.97 | G12: 13.65 | H12: 4.6 | I12: 8.26 | J12: 3.1 | K12: 6.3 | L12: =+SUM(F12:K12) -> 59.88 | M12: Penilaian prasarana fisik 2022 dan non prasarana fisik 2022 | P12: =(F12*C12)/$C$42 -> 1.1386996 | Q12: =(G12*C12)/$C$42 -> 0.64844595 | R12: =(H12*C12)/$C$42 -> 0.21852391 | S12: =(I12*C12)/$C$42 -> 0.39239293 | T12: =(J12*C12)/$C$42 -> 0.14726611 | U12: =(K12*C12)/$C$42 -> 0.29928274 | X12: =(F12*C12)/$C$202 -> 0.065544313 | Y12: =(G12*C12)/$C$202 -> 0.037324984 | Z12: =(H12*C12)/$C$202 -> 0.012578383 | AA12: =(I12*C12)/$C$202 -> 0.022586401 | AB12: =(J12*C12)/$C$202 -> 0.0084767364 | AC12: =(K12*C12)/$C$202 -> 0.017226916
A13: 7 | B13: D.I. Kebalon | C13: 107 | D13: Kab./Kota Malang | E13: 35000007 | F13: 29.45 | G13: 13.38 | H13: 6 | I13: 6.5 | J13: 3.1 | K13: 3.2 | L13: =+SUM(F13:K13) -> 61.63 | M13: Penilaian prasarana fisik 2022 dan non prasarana fisik 2022 | P13: =(F13*C13)/$C$42 -> 0.32756237 | Q13: =(G13*C13)/$C$42 -> 0.14882121 | R13: =(H13*C13)/$C$42 -> 0.066735967 | S13: =(I13*C13)/$C$42 -> 0.072297297 | T13: =(J13*C13)/$C$42 -> 0.034480249 | U13: =(K13*C13)/$C$42 -> 0.035592516 | X13: =(F13*C13)/$C$202 -> 0.01885471 | Y13: =(G13*C13)/$C$202 -> 0.0085662486 | Z13: =(H13*C13)/$C$202 -> 0.0038413671 | AA13: =(I13*C13)/$C$202 -> 0.004161481 | AB13: =(J13*C13)/$C$202 -> 0.0019847063 | AC13: =(K13*C13)/$C$202 -> 0.0020487291
A14: 8 | B14: D.I. Losawi | C14: 39 | D14: Kab./Kota Malang | E14: 35000008 | F14: 28.57 | G14: 14.35 | H14: 4.6 | I14: 7.7 | J14: 3.1 | K14: 3 | L14: =+SUM(F14:K14) -> 61.32 | M14: Penilaian prasarana fisik 2022 dan non prasarana fisik 2022 | P14: =(F14*C14)/$C$42 -> 0.11582432 | Q14: =(G14*C14)/$C$42 -> 0.058175676 | R14: =(H14*C14)/$C$42 -> 0.018648649 | S14: =(I14*C14)/$C$42 -> 0.031216216 | T14: =(J14*C14)/$C$42 -> 0.012567568 | U14: =(K14*C14)/$C$42 -> 0.012162162 | X14: =(F14*C14)/$C$202 -> 0.0066669259 | Y14: =(G14*C14)/$C$202 -> 0.003348631 | Z14: =(H14*C14)/$C$202 -> 0.0010734287 | AA14: =(I14*C14)/$C$202 -> 0.0017968264 | AB14: =(J14*C14)/$C$202 -> 0.00072339764 | AC14: =(K14*C14)/$C$202 -> 0.00070006223
A15: 9 | B15: D.I. Ngukir | C15: 282 | D15: Kab. Malang, Kota Batu | E15: 35000009 | F15: 28.48 | G15: 13.54 | H15: 3.9 | I15: 9.7 | J15: 3 | K15: 3 | L15: =+SUM(F15:K15) -> 61.62 | M15: Penilaian prasarana fisik 2022 dan non prasarana fisik 2022 | P15: =(F15*C15)/$C$42 -> 0.83486071 | Q15: =(G15*C15)/$C$42 -> 0.3969106 | R15: =(H15*C15)/$C$42 -> 0.11432432 | S15: =(I15*C15)/$C$42 -> 0.28434511 | T15: =(J15*C15)/$C$42 -> 0.087941788 | U15: =(K15*C15)/$C$42 -> 0.087941788 | X15: =(F15*C15)/$C$202 -> 0.048055143 | Y15: =(G15*C15)/$C$202 -> 0.022846441 | Z15: =(H15*C15)/$C$202 -> 0.0065805849 | AA15: =(I15*C15)/$C$202 -> 0.016367096 | AB15: =(J15*C15)/$C$202 -> 0.0050619884 | AC15: =(K15*C15)/$C$202 -> 0.0050619884
A16: 10 | B16: D.I. Pakis | C16: 726 | D16: Kab./Kota Malang | E16: 35000010 | F16: 31.96 | G16: 13.27 | H16: 5.9 | I16: 6.5 | J16: 3.1 | K16: 3 | L16: =+SUM(F16:K16) -> 63.73 | M16: Penilaian prasarana fisik 2022 dan non prasarana fisik 2022 | P16: =(F16*C16)/$C$42 -> 2.4119501 | Q16: =(G16*C16)/$C$42 -> 1.0014574 | R16: =(H16*C16)/$C$42 -> 0.44525988 | S16: =(I16*C16)/$C$42 -> 0.49054054 | T16: =(J16*C16)/$C$42 -> 0.2339501 | U16: =(K16*C16)/$C$42 -> 0.22640333 | X16: =(F16*C16)/$C$202 -> 0.13883347 | Y16: =(G16*C16)/$C$202 -> 0.05764456 | Z16: =(H16*C16)/$C$202 -> 0.025629458 | AA16: =(I16*C16)/$C$202 -> 0.028235843 | AB16: =(J16*C16)/$C$202 -> 0.013466325 | AC16: =(K16*C16)/$C$202 -> 0.013031928
A17: 11 | B17: D.I. Peniwen | C17: 63 | D17: Kab./Kota Malang | E17: 35000011 | F17: 27.57 | G17: 13.46 | H17: 6.5 | I17: 6.5 | J17: 3.1 | K17: 3.2 | L17: =+SUM(F17:K17) -> 60.33 | M17: Penilaian prasarana fisik 2022 dan non prasarana fisik 2022 | P17: =(F17*C17)/$C$42 -> 0.18055198 | Q17: =(G17*C17)/$C$42 -> 0.088147609 | R17: =(H17*C17)/$C$42 -> 0.042567568 | S17: =(I17*C17)/$C$42 -> 0.042567568 | T17: =(J17*C17)/$C$42 -> 0.020301455 | U17: =(K17*C17)/$C$42 -> 0.020956341 | X17: =(F17*C17)/$C$202 -> 0.010392693 | Y17: =(G17*C17)/$C$202 -> 0.0050738356 | Z17: =(H17*C17)/$C$202 -> 0.0024502178 | AA17: =(I17*C17)/$C$202 -> 0.0024502178 | AB17: =(J17*C17)/$C$202 -> 0.0011685654 | AC17: =(K17*C17)/$C$202 -> 0.0012062611
A18: 12 | B18: D.I. Podokaton | C18: 70 | D18: Kab./Kota Malang | E18: 35000012 | F18: 28.39 | G18: 15 | H18: 5.5 | I18: 7.14 | J18: 3.1 | K18: 3 | L18: =+SUM(F18:K18) -> 62.13 | M18: Penilaian prasarana fisik 2022 dan non prasarana fisik 2022 | P18: =(F18*C18)/$C$42 -> 0.20658004 | Q18: =(G18*C18)/$C$42 -> 0.10914761 | R18: =(H18*C18)/$C$42 -> 0.04002079 | S18: =(I18*C18)/$C$42 -> 0.051954262 | T18: =(J18*C18)/$C$42 -> 0.022557173 | U18: =(K18*C18)/$C$42 -> 0.021829522 | X18: =(F18*C18)/$C$202 -> 0.011890886 | Y18: =(G18*C18)/$C$202 -> 0.0062826097 | Z18: =(H18*C18)/$C$202 -> 0.0023036236 | AA18: =(I18*C18)/$C$202 -> 0.0029905222 | AB18: =(J18*C18)/$C$202 -> 0.001298406 | AC18: =(K18*C18)/$C$202 -> 0.0012565219
... A30: 24 | B30: D.I. Jempor | C30: 54 | D30: Kab./Kota Blitar | E30: 35000025 | F30: 29.82 | G30: 13.51 | H30: 6 | I30: 10.5 | J30: 3.5 | K30: 7 | L30: =+SUM(F30:K30) -> 70.33 | M30: Penilaian prasarana fisik 2022 dan non prasarana fisik 2022 | P30: =(F30*C30)/$C$42 -> 0.16738877 | Q30: =(G30*C30)/$C$42 -> 0.075835759 | R30: =(H30*C30)/$C$42 -> 0.033679834 | S30: =(I30*C30)/$C$42 -> 0.058939709 | T30: =(J30*C30)/$C$42 -> 0.01964657 | U30: =(K30*C30)/$C$42 -> 0.039293139 | X30: =(F30*C30)/$C$202 -> 0.0096350103 | Y30: =(G30*C30)/$C$202 -> 0.0043651572 | Z30: =(H30*C30)/$C$202 -> 0.0019386339 | AA30: =(I30*C30)/$C$202 -> 0.0033926093 | AB30: =(J30*C30)/$C$202 -> 0.0011308698 | AC30: =(K30*C30)/$C$202 -> 0.0022617395
A31: 25 | B31: D.I. Tambakrejo I | C31: 23 | D31: Kab./Kota Blitar | E31: 35000026 | F31: 29.66 | G31: 13.53 | H31: 7 | I31: 10.5 | J31: 3.5 | K31: 7 | L31: 7 | M31: Penilaian prasarana fisik 2022 dan non prasarana fisik 2022 | P31: =(F31*C31)/$C$42 -> 0.070912682 | Q31: =(G31*C31)/$C$42 -> 0.032348233 | R31: =(H31*C31)/$C$42 -> 0.016735967 | S31: =(I31*C31)/$C$42 -> 0.02510395 | T31: =(J31*C31)/$C$42 -> 0.0083679834 | U31: =(K31*C31)/$C$42 -> 0.016735967 | X31: =(F31*C31)/$C$202 -> 0.0040817816 | Y31: =(G31*C31)/$C$202 -> 0.001861986 | Z31: =(H31*C31)/$C$202 -> 0.00096333349 | AA31: =(I31*C31)/$C$202 -> 0.0014450002 | AB31: =(J31*C31)/$C$202 -> 0.00048166675 | AC31: =(K31*C31)/$C$202 -> 0.00096333349
A32: 26 | B32: D.I. Rembang | C32: 42 | D32: Kab./Kota Blitar | E32: 35000027 | F32: 28.87 | G32: 13.15 | H32: 7 | I32: 10.5 | J32: 3.5 | K32: 7 | L32: =+SUM(F32:K32) -> 70.02 | M32: Penilaian prasarana fisik 2022 dan non prasarana fisik 2022 | P32: =(F32*C32)/$C$42 -> 0.12604366 | Q32: =(G32*C32)/$C$42 -> 0.057411642 | R32: =(H32*C32)/$C$42 -> 0.030561331 | S32: =(I32*C32)/$C$42 -> 0.045841996 | T32: =(J32*C32)/$C$42 -> 0.015280665 | U32: =(K32*C32)/$C$42 -> 0.030561331 | X32: =(F32*C32)/$C$202 -> 0.0072551577 | Y32: =(G32*C32)/$C$202 -> 0.0033046527 | Z32: =(H32*C32)/$C$202 -> 0.0017591307 | AA32: =(I32*C32)/$C$202 -> 0.0026386961 | AB32: =(J32*C32)/$C$202 -> 0.00087956536 | AC32: =(K32*C32)/$C$202 -> 0.0017591307
A33: 27 | B33: D.I. Plosotengah | C33: 51 | D33: Kab./Kota Blitar | E33: 35000028 | F33: 13.8 | G33: 13.22 | H33: 7 | I33: 10.5 | J33: 3.5 | K33: 7 | L33: =+SUM(F33:K33) -> 55.02 | M33: Penilaian prasarana fisik 2022 dan non prasarana fisik 2022 | P33: =(F33*C33)/$C$42 -> 0.073160083 | Q33: =(G33*C33)/$C$42 -> 0.070085239 | R33: =(H33*C33)/$C$42 -> 0.037110187 | S33: =(I33*C33)/$C$42 -> 0.055665281 | T33: =(J33*C33)/$C$42 -> 0.018555094 | U33: =(K33*C33)/$C$42 -> 0.037110187 | X33: =(F33*C33)/$C$202 -> 0.0042111436 | Y33: =(G33*C33)/$C$202 -> 0.0040341535 | Z33: =(H33*C33)/$C$202 -> 0.0021360873 | AA33: =(I33*C33)/$C$202 -> 0.003204131 | AB33: =(J33*C33)/$C$202 -> 0.0010680437 | AC33: =(K33*C33)/$C$202 -> 0.0021360873
A34: 28 | B34: D.I. Sawahan | C34: 82 | D34: Kab./Kota Blitar | E34: 35000029 | F34: 27.48 | G34: 13.52 | H34: 7 | I34: 10.5 | J34: 3.5 | K34: 7 | L34: =+SUM(F34:K34) -> 69 | M34: Penilaian prasarana fisik 2022 dan non prasarana fisik 2022 | P34: =(F34*C34)/$C$42 -> 0.23423701 | Q34: =(G34*C34)/$C$42 -> 0.11524324 | R34: =(H34*C34)/$C$42 -> 0.05966736 | S34: =(I34*C34)/$C$42 -> 0.08950104 | T34: =(J34*C34)/$C$42 -> 0.02983368 | U34: =(K34*C34)/$C$42 -> 0.05966736 | X34: =(F34*C34)/$C$202 -> 0.01348284 | Y34: =(G34*C34)/$C$202 -> 0.0066334785 | Z34: =(H34*C34)/$C$202 -> 0.0034344933 | AA34: =(I34*C34)/$C$202 -> 0.00515174 | AB34: =(J34*C34)/$C$202 -> 0.0017172467 | AC34: =(K34*C34)/$C$202 -> 0.0034344933
